(dvenv) aylen@aylen-HP-Pavilion-Laptop-15-eg0xxx:~/Documentos/IS2/proyectoIS/proyecto$ python manage.py migrate
Traceback (most recent call last):
  File "/home/aylen/Documentos/IS2/proyectoIS/dvenv/lib/python3.12/site-packages/django/db/backends/base/base.py", line 279, in ensure_connection
    self.connect()
  File "/home/aylen/Documentos/IS2/proyectoIS/dvenv/lib/python3.12/site-packages/django/utils/asyncio.py", line 26, in inner
    return func(*args, **kwargs)
           ^^^^^^^^^^^^^^^^^^^^^
  File "/home/aylen/Documentos/IS2/proyectoIS/dvenv/lib/python3.12/site-packages/django/db/backends/base/base.py", line 256, in connect
    self.connection = self.get_new_connection(conn_params)
                      ^^^^^^^^^^^^^^^^^^^^^^^^^^^^^^^^^^^^
  File "/home/aylen/Documentos/IS2/proyectoIS/dvenv/lib/python3.12/site-packages/django/utils/asyncio.py", line 26, in inner
    return func(*args, **kwargs)
           ^^^^^^^^^^^^^^^^^^^^^
  File "/home/aylen/Documentos/IS2/proyectoIS/dvenv/lib/python3.12/site-packages/django/db/backends/postgresql/base.py", line 332, in get_new_connection
    connection = self.Database.connect(**conn_params)
                 ^^^^^^^^^^^^^^^^^^^^^^^^^^^^^^^^^^^^
  File "/home/aylen/Documentos/IS2/proyectoIS/dvenv/lib/python3.12/site-packages/psycopg2/__init__.py", line 122, in connect
    conn = _connect(dsn, connection_factory=connection_factory, **kwasync)
           ^^^^^^^^^^^^^^^^^^^^^^^^^^^^^^^^^^^^^^^^^^^^^^^^^^^^^^^^^^^^^^^
psycopg2.OperationalError: connection to server at "localhost" (127.0.0.1), port 5432 failed: fe_sendauth: no password supplied


The above exception was the direct cause of the following exception:

Traceback (most recent call last):
  File "/home/aylen/Documentos/IS2/proyectoIS/proyecto/manage.py", line 22, in <module>
    main()
  File "/home/aylen/Documentos/IS2/proyectoIS/proyecto/manage.py", line 18, in main
    execute_from_command_line(sys.argv)
  File "/home/aylen/Documentos/IS2/proyectoIS/dvenv/lib/python3.12/site-packages/django/core/management/__init__.py", line 442, in execute_from_command_line
    utility.execute()
  File "/home/aylen/Documentos/IS2/proyectoIS/dvenv/lib/python3.12/site-packages/django/core/management/__init__.py", line 436, in execute
    self.fetch_command(subcommand).run_from_argv(self.argv)
  File "/home/aylen/Documentos/IS2/proyectoIS/dvenv/lib/python3.12/site-packages/django/core/management/base.py", line 416, in run_from_argv
    self.execute(*args, **cmd_options)
  File "/home/aylen/Documentos/IS2/proyectoIS/dvenv/lib/python3.12/site-packages/django/core/management/base.py", line 460, in execute
    output = self.handle(*args, **options)
             ^^^^^^^^^^^^^^^^^^^^^^^^^^^^^
  File "/home/aylen/Documentos/IS2/proyectoIS/dvenv/lib/python3.12/site-packages/django/core/management/base.py", line 107, in wrapper
    res = handle_func(*args, **kwargs)
          ^^^^^^^^^^^^^^^^^^^^^^^^^^^^
  File "/home/aylen/Documentos/IS2/proyectoIS/dvenv/lib/python3.12/site-packages/django/core/management/commands/migrate.py", line 114, in handle
    executor = MigrationExecutor(connection, self.migration_progress_callback)
               ^^^^^^^^^^^^^^^^^^^^^^^^^^^^^^^^^^^^^^^^^^^^^^^^^^^^^^^^^^^^^^^
  File "/home/aylen/Documentos/IS2/proyectoIS/dvenv/lib/python3.12/site-packages/django/db/migrations/executor.py", line 18, in __init__
    self.loader = MigrationLoader(self.connection)
                  ^^^^^^^^^^^^^^^^^^^^^^^^^^^^^^^^
  File "/home/aylen/Documentos/IS2/proyectoIS/dvenv/lib/python3.12/site-packages/django/db/migrations/loader.py", line 58, in __init__
    self.build_graph()
  File "/home/aylen/Documentos/IS2/proyectoIS/dvenv/lib/python3.12/site-packages/django/db/migrations/loader.py", line 235, in build_graph
    self.applied_migrations = recorder.applied_migrations()
                              ^^^^^^^^^^^^^^^^^^^^^^^^^^^^^
  File "/home/aylen/Documentos/IS2/proyectoIS/dvenv/lib/python3.12/site-packages/django/db/migrations/recorder.py", line 89, in applied_migrations
    if self.has_table():
       ^^^^^^^^^^^^^^^^
  File "/home/aylen/Documentos/IS2/proyectoIS/dvenv/lib/python3.12/site-packages/django/db/migrations/recorder.py", line 63, in has_table
    with self.connection.cursor() as cursor:
         ^^^^^^^^^^^^^^^^^^^^^^^^
  File "/home/aylen/Documentos/IS2/proyectoIS/dvenv/lib/python3.12/site-packages/django/utils/asyncio.py", line 26, in inner
    return func(*args, **kwargs)
           ^^^^^^^^^^^^^^^^^^^^^
  File "/home/aylen/Documentos/IS2/proyectoIS/dvenv/lib/python3.12/site-packages/django/db/backends/base/base.py", line 320, in cursor
    return self._cursor()
           ^^^^^^^^^^^^^^
  File "/home/aylen/Documentos/IS2/proyectoIS/dvenv/lib/python3.12/site-packages/django/db/backends/base/base.py", line 296, in _cursor
    self.ensure_connection()
  File "/home/aylen/Documentos/IS2/proyectoIS/dvenv/lib/python3.12/site-packages/django/utils/asyncio.py", line 26, in inner
    return func(*args, **kwargs)
           ^^^^^^^^^^^^^^^^^^^^^
  File "/home/aylen/Documentos/IS2/proyectoIS/dvenv/lib/python3.12/site-packages/django/db/backends/base/base.py", line 278, in ensure_connection
    with self.wrap_database_errors:
  File "/home/aylen/Documentos/IS2/proyectoIS/dvenv/lib/python3.12/site-packages/django/db/utils.py", line 91, in __exit__
    raise dj_exc_value.with_traceback(traceback) from exc_value
  File "/home/aylen/Documentos/IS2/proyectoIS/dvenv/lib/python3.12/site-packages/django/db/backends/base/base.py", line 279, in ensure_connection
    self.connect()
  File "/home/aylen/Documentos/IS2/proyectoIS/dvenv/lib/python3.12/site-packages/django/utils/asyncio.py", line 26, in inner
    return func(*args, **kwargs)
           ^^^^^^^^^^^^^^^^^^^^^
  File "/home/aylen/Documentos/IS2/proyectoIS/dvenv/lib/python3.12/site-packages/django/db/backends/base/base.py", line 256, in connect
    self.connection = self.get_new_connection(conn_params)
                      ^^^^^^^^^^^^^^^^^^^^^^^^^^^^^^^^^^^^
  File "/home/aylen/Documentos/IS2/proyectoIS/dvenv/lib/python3.12/site-packages/django/utils/asyncio.py", line 26, in inner
    return func(*args, **kwargs)
           ^^^^^^^^^^^^^^^^^^^^^
  File "/home/aylen/Documentos/IS2/proyectoIS/dvenv/lib/python3.12/site-packages/django/db/backends/postgresql/base.py", line 332, in get_new_connection
    connection = self.Database.connect(**conn_params)
                 ^^^^^^^^^^^^^^^^^^^^^^^^^^^^^^^^^^^^
  File "/home/aylen/Documentos/IS2/proyectoIS/dvenv/lib/python3.12/site-packages/psycopg2/__init__.py", line 122, in connect
    conn = _connect(dsn, connection_factory=connection_factory, **kwasync)
           ^^^^^^^^^^^^^^^^^^^^^^^^^^^^^^^^^^^^^^^^^^^^^^^^^^^^^^^^^^^^^^^
django.db.utils.OperationalError: connection to server at "localhost" (127.0.0.1), port 5432 failed: fe_sendauth: no password supplied


El error indica que Django no puede conectarse a PostgreSQL porque **falta la contraseña** en la configuración. Necesito revisar tu configuración de base de datos. 

Leer [](file:///home/aylen/Documentos/IS2/proyectoIS/proyecto/proyecto/settings.py#70-70), líneas 70 a 90

Veo el problema. Tu configuración está buscando la contraseña en una variable de entorno `DB_PASSWORD`, pero no la has definido. Tienes estas opciones:

## Opción 1: Definir la variable de entorno (Recomendado)

```bash
# Exportar la variable de entorno con tu contraseña de PostgreSQL
export DB_PASSWORD=tu_contraseña_postgresql

# Luego ejecutar migrate
python manage.py migrate
```

## Opción 2: Crear un archivo .env con las credenciales

```bash
# Crear archivo .env en el directorio del proyecto
echo "DB_PASSWORD=tu_contraseña_postgresql" > .env
```

## Opción 3: Verificar el resto de la configuración 

Leer [](file:///home/aylen/Documentos/IS2/proyectoIS/proyecto/proyecto/settings.py#85-85), líneas 85 a 95

## Solución rápida:

```bash
# Desde el directorio del proyecto
export DB_PASSWORD=tu_contraseña_de_postgres

# Ahora crear migraciones y aplicarlas
python manage.py makemigrations
python manage.py migrate
```

## O si no recuerdas tu contraseña de PostgreSQL:

```bash
# Cambiar contraseña del usuario postgres
sudo -u postgres psql -c "ALTER USER postgres PASSWORD 'nueva_contraseña';"

# Luego usar esa contraseña
export DB_PASSWORD=nueva_contraseña
python manage.py migrate
```

**Resumen de tus datos de BD:**
- **Nombre de BD:** `bd_desarrollo`
- **Usuario:** `postgres`
- **Necesitas:** definir `DB_PASSWORD` con tu contraseña de PostgreSQL

¿Conoces tu contraseña de PostgreSQL o necesitas cambiarla?